Workbook

Sheet Legend
A1: AstraWMS Requirements Traceability Matrix
A2: Source | B2: AstraWMS Scope & Solution Definition v1.0 (docs/scope/*.md), baseline 2026-09-30. Every requirement ID, exception code and interface ID in the document set is one row on the RTM sheet.
A3: How to use | B3: Maintain only the yellow-header columns on the RTM sheet (Fit-Gap Disposition, Design Reference, Test Status, Defect ID(s), Owner). Summary recalculates automatically. Add further test cases for a requirement as extra rows with the same Req ID and TC suffix -02, -03 …
A5: Column | B5: Meaning
A6: Req ID | B6: Identifier from the scope documents: <AREA>-<NNN> requirement, <AREA>-EX-<NN> exception flow, IF-<FLOW>-<NNN> ERP interface.
A7: Type | B7: Requirement | Exception | Interface.
A8: Area / Section / Source Document | B8: Functional area (from the ID prefix), the heading it appears under, and the Markdown file that defines it.
A9: Requirement / Exception | B9: Requirement text, exception name, or interface object/direction/trigger as written in the scope.
A10: Acceptance Criteria | B10: Rules: enforced as stated (positive + negative case). Exceptions: detection, resolution and ERP impact from the exception table. Interfaces: SAP/Oracle technology, design peak volume and latency SLA. HA/DR NFRs: the stated target.
A11: Priority | B11: MoSCoW: M Must, S Should, C Could, W Won't (document §0.4).
A12: Fit-Gap Disposition (input) | B12: Blueprint outcome (§I.1.2): Fit - Standard, Fit - Configuration, Gap - Extension, Gap - Process Change, Rejected, Deferred.
A13: Design Reference (input) | B13: Process Design Document (PDD) or Interface Specification Document (ISD) reference.
A14: Test Case ID | B14: Generated placeholder TC-<ReqID>-01; replace/extend with IDs from the test management tool.
... A18: Example (filled row) | B18: Req ID INB-002 · Fit-Gap Disposition: Fit - Configuration · Design Reference: PDD-INB-01 §3.2 · Test Status: Passed · Defect ID(s): DEF-0142 (closed) · Owner: Receiving Process Owner
A20: Assumptions
A21: A1 | B21: Exception codes carry no priority in the scope; they are set to M because §I.2 requires every exception code to be covered by a test case.
A22: A2 | B22: NFR-020 to NFR-030 (HA/DR) list a target instead of a priority; they are set to M.
A23: A3 | B23: Interfaces IF-* are set to M; drop to S/C per site if an interface is not used (e.g. kitting IF-KIT-001 at sites without kitting).
A24: A4 | B24: Where a priority carries a qualifier (e.g. 'M (if sorter in scope)'), the letter is used and the qualifier is kept in Notes.
A25: A5 | B25: Test Type and Phase are proposals derived from the requirement wording (latency/throughput targets → Performance; e-signature/Part 11 → Regulated validation). Confirm during test planning.
A26: Coverage gap | B26: Tables without requirement IDs are not in the RTM: §E.4 Security & Compliance, §E.6 API Governance, §D.5 Integration Security, §G.2 Web UI modules, §H KPI definitions and reports. Assign IDs in the scope document to trace them.

Sheet Summary
A1: AstraWMS: Requirements Traceability Summary
A2: All figures are formulas over the RTM sheet and update as Test Status / Fit-Gap Disposition are maintained.
A4: Area | B4: Total Items | C4: Requirements | D4: Interfaces | E4: Exceptions | F4: Must (M) | G4: Should (S) | H4: Could (C) | I4: Fit-Gap Assessed | J4: Passed | K4: Failed / Blocked | L4: In Progress | M4: Not Started | N4: % Passed | O4: % Fit-Gap Assessed
A5: Inbound | B5: =COUNTIFS(RTM!$C$2:$C$247,$A5) | C5: =COUNTIFS(RTM!$C$2:$C$247,$A5,RTM!$B$2:$B$247,"Requirement") | D5: =COUNTIFS(RTM!$C$2:$C$247,$A5,RTM!$B$2:$B$247,"Interface") | E5: =COUNTIFS(RTM!$C$2:$C$247,$A5,RTM!$B$2:$B$247,"Exception") | F5: =COUNTIFS(RTM!$C$2:$C$247,$A5,RTM!$H$2:$H$247,"M") | G5: =COUNTIFS(RTM!$C$2:$C$247,$A5,RTM!$H$2:$H$247,"S") | H5: =COUNTIFS(RTM!$C$2:$C$247,$A5,RTM!$H$2:$H$247,"C") | I5: =COUNTIFS(RTM!$C$2:$C$247,$A5,RTM!$I$2:$I$247,"?*") | J5: =COUNTIFS(RTM!$C$2:$C$247,$A5,RTM!$N$2:$N$247,"Passed") | K5: =COUNTIFS(RTM!$C$2:$C$247,$A5,RTM!$N$2:$N$247,"Failed")+COUNTIFS(RTM!$C$2:$C$247,$A5,RTM!$N$2:$N$247,"Blocked") | L5: =COUNTIFS(RTM!$C$2:$C$247,$A5,RTM!$N$2:$N$247,"In Progress") | M5: =COUNTIFS(RTM!$C$2:$C$247,$A5,RTM!$N$2:$N$247,"Not Started") | N5: =IFERROR(J5/B5,0) | O5: =IFERROR(I5/B5,0)
A6: Putaway & Storage | B6: =COUNTIFS(RTM!$C$2:$C$247,$A6) | C6: =COUNTIFS(RTM!$C$2:$C$247,$A6,RTM!$B$2:$B$247,"Requirement") | D6: =COUNTIFS(RTM!$C$2:$C$247,$A6,RTM!$B$2:$B$247,"Interface") | E6: =COUNTIFS(RTM!$C$2:$C$247,$A6,RTM!$B$2:$B$247,"Exception") | F6: =COUNTIFS(RTM!$C$2:$C$247,$A6,RTM!$H$2:$H$247,"M") | G6: =COUNTIFS(RTM!$C$2:$C$247,$A6,RTM!$H$2:$H$247,"S") | H6: =COUNTIFS(RTM!$C$2:$C$247,$A6,RTM!$H$2:$H$247,"C") | I6: =COUNTIFS(RTM!$C$2:$C$247,$A6,RTM!$I$2:$I$247,"?*") | J6: =COUNTIFS(RTM!$C$2:$C$247,$A6,RTM!$N$2:$N$247,"Passed") | K6: =COUNTIFS(RTM!$C$2:$C$247,$A6,RTM!$N$2:$N$247,"Failed")+COUNTIFS(RTM!$C$2:$C$247,$A6,RTM!$N$2:$N$247,"Blocked") | L6: =COUNTIFS(RTM!$C$2:$C$247,$A6,RTM!$N$2:$N$247,"In Progress") | M6: =COUNTIFS(RTM!$C$2:$C$247,$A6,RTM!$N$2:$N$247,"Not Started") | N6: =IFERROR(J6/B6,0) | O6: =IFERROR(I6/B6,0)
A7: Outbound Order Mgmt | B7: =COUNTIFS(RTM!$C$2:$C$247,$A7) | C7: =COUNTIFS(RTM!$C$2:$C$247,$A7,RTM!$B$2:$B$247,"Requirement") | D7: =COUNTIFS(RTM!$C$2:$C$247,$A7,RTM!$B$2:$B$247,"Interface") | E7: =COUNTIFS(RTM!$C$2:$C$247,$A7,RTM!$B$2:$B$247,"Exception") | F7: =COUNTIFS(RTM!$C$2:$C$247,$A7,RTM!$H$2:$H$247,"M") | G7: =COUNTIFS(RTM!$C$2:$C$247,$A7,RTM!$H$2:$H$247,"S") | H7: =COUNTIFS(RTM!$C$2:$C$247,$A7,RTM!$H$2:$H$247,"C") | I7: =COUNTIFS(RTM!$C$2:$C$247,$A7,RTM!$I$2:$I$247,"?*") | J7: =COUNTIFS(RTM!$C$2:$C$247,$A7,RTM!$N$2:$N$247,"Passed") | K7: =COUNTIFS(RTM!$C$2:$C$247,$A7,RTM!$N$2:$N$247,"Failed")+COUNTIFS(RTM!$C$2:$C$247,$A7,RTM!$N$2:$N$247,"Blocked") | L7: =COUNTIFS(RTM!$C$2:$C$247,$A7,RTM!$N$2:$N$247,"In Progress") | M7: =COUNTIFS(RTM!$C$2:$C$247,$A7,RTM!$N$2:$N$247,"Not Started") | N7: =IFERROR(J7/B7,0) | O7: =IFERROR(I7/B7,0)
A8: Picking | B8: =COUNTIFS(RTM!$C$2:$C$247,$A8) | C8: =COUNTIFS(RTM!$C$2:$C$247,$A8,RTM!$B$2:$B$247,"Requirement") | D8: =COUNTIFS(RTM!$C$2:$C$247,$A8,RTM!$B$2:$B$247,"Interface") | E8: =COUNTIFS(RTM!$C$2:$C$247,$A8,RTM!$B$2:$B$247,"Exception") | F8: =COUNTIFS(RTM!$C$2:$C$247,$A8,RTM!$H$2:$H$247,"M") | G8: =COUNTIFS(RTM!$C$2:$C$247,$A8,RTM!$H$2:$H$247,"S") | H8: =COUNTIFS(RTM!$C$2:$C$247,$A8,RTM!$H$2:$H$247,"C") | I8: =COUNTIFS(RTM!$C$2:$C$247,$A8,RTM!$I$2:$I$247,"?*") | J8: =COUNTIFS(RTM!$C$2:$C$247,$A8,RTM!$N$2:$N$247,"Passed") | K8: =COUNTIFS(RTM!$C$2:$C$247,$A8,RTM!$N$2:$N$247,"Failed")+COUNTIFS(RTM!$C$2:$C$247,$A8,RTM!$N$2:$N$247,"Blocked") | L8: =COUNTIFS(RTM!$C$2:$C$247,$A8,RTM!$N$2:$N$247,"In Progress") | M8: =COUNTIFS(RTM!$C$2:$C$247,$A8,RTM!$N$2:$N$247,"Not Started") | N8: =IFERROR(J8/B8,0) | O8: =IFERROR(I8/B8,0)
A9: Packing, Staging & Shipping | B9: =COUNTIFS(RTM!$C$2:$C$247,$A9) | C9: =COUNTIFS(RTM!$C$2:$C$247,$A9,RTM!$B$2:$B$247,"Requirement") | D9: =COUNTIFS(RTM!$C$2:$C$247,$A9,RTM!$B$2:$B$247,"Interface") | E9: =COUNTIFS(RTM!$C$2:$C$247,$A9,RTM!$B$2:$B$247,"Exception") | F9: =COUNTIFS(RTM!$C$2:$C$247,$A9,RTM!$H$2:$H$247,"M") | G9: =COUNTIFS(RTM!$C$2:$C$247,$A9,RTM!$H$2:$H$247,"S") | H9: =COUNTIFS(RTM!$C$2:$C$247,$A9,RTM!$H$2:$H$247,"C") | I9: =COUNTIFS(RTM!$C$2:$C$247,$A9,RTM!$I$2:$I$247,"?*") | J9: =COUNTIFS(RTM!$C$2:$C$247,$A9,RTM!$N$2:$N$247,"Passed") | K9: =COUNTIFS(RTM!$C$2:$C$247,$A9,RTM!$N$2:$N$247,"Failed")+COUNTIFS(RTM!$C$2:$C$247,$A9,RTM!$N$2:$N$247,"Blocked") | L9: =COUNTIFS(RTM!$C$2:$C$247,$A9,RTM!$N$2:$N$247,"In Progress") | M9: =COUNTIFS(RTM!$C$2:$C$247,$A9,RTM!$N$2:$N$247,"Not Started") | N9: =IFERROR(J9/B9,0) | O9: =IFERROR(I9/B9,0)
A10: Inventory Management | B10: =COUNTIFS(RTM!$C$2:$C$247,$A10) | C10: =COUNTIFS(RTM!$C$2:$C$247,$A10,RTM!$B$2:$B$247,"Requirement") | D10: =COUNTIFS(RTM!$C$2:$C$247,$A10,RTM!$B$2:$B$247,"Interface") | E10: =COUNTIFS(RTM!$C$2:$C$247,$A10,RTM!$B$2:$B$247,"Exception") | F10: =COUNTIFS(RTM!$C$2:$C$247,$A10,RTM!$H$2:$H$247,"M") | G10: =COUNTIFS(RTM!$C$2:$C$247,$A10,RTM!$H$2:$H$247,"S") | H10: =COUNTIFS(RTM!$C$2:$C$247,$A10,RTM!$H$2:$H$247,"C") | I10: =COUNTIFS(RTM!$C$2:$C$247,$A10,RTM!$I$2:$I$247,"?*") | J10: =COUNTIFS(RTM!$C$2:$C$247,$A10,RTM!$N$2:$N$247,"Passed") | K10: =COUNTIFS(RTM!$C$2:$C$247,$A10,RTM!$N$2:$N$247,"Failed")+COUNTIFS(RTM!$C$2:$C$247,$A10,RTM!$N$2:$N$247,"Blocked") | L10: =COUNTIFS(RTM!$C$2:$C$247,$A10,RTM!$N$2:$N$247,"In Progress") | M10: =COUNTIFS(RTM!$C$2:$C$247,$A10,RTM!$N$2:$N$247,"Not Started") | N10: =IFERROR(J10/B10,0) | O10: =IFERROR(I10/B10,0)
A11: Replenishment | B11: =COUNTIFS(RTM!$C$2:$C$247,$A11) | C11: =COUNTIFS(RTM!$C$2:$C$247,$A11,RTM!$B$2:$B$247,"Requirement") | D11: =COUNTIFS(RTM!$C$2:$C$247,$A11,RTM!$B$2:$B$247,"Interface") | E11: =COUNTIFS(RTM!$C$2:$C$247,$A11,RTM!$B$2:$B$247,"Exception") | F11: =COUNTIFS(RTM!$C$2:$C$247,$A11,RTM!$H$2:$H$247,"M") | G11: =COUNTIFS(RTM!$C$2:$C$247,$A11,RTM!$H$2:$H$247,"S") | H11: =COUNTIFS(RTM!$C$2:$C$247,$A11,RTM!$H$2:$H$247,"C") | I11: =COUNTIFS(RTM!$C$2:$C$247,$A11,RTM!$I$2:$I$247,"?*") | J11: =COUNTIFS(RTM!$C$2:$C$247,$A11,RTM!$N$2:$N$247,"Passed") | K11: =COUNTIFS(RTM!$C$2:$C$247,$A11,RTM!$N$2:$N$247,"Failed")+COUNTIFS(RTM!$C$2:$C$247,$A11,RTM!$N$2:$N$247,"Blocked") | L11: =COUNTIFS(RTM!$C$2:$C$247,$A11,RTM!$N$2:$N$247,"In Progress") | M11: =COUNTIFS(RTM!$C$2:$C$247,$A11,RTM!$N$2:$N$247,"Not Started") | N11: =IFERROR(J11/B11,0) | O11: =IFERROR(I11/B11,0)
A12: Returns | B12: =COUNTIFS(RTM!$C$2:$C$247,$A12) | C12: =COUNTIFS(RTM!$C$2:$C$247,$A12,RTM!$B$2:$B$247,"Requirement") | D12: =COUNTIFS(RTM!$C$2:$C$247,$A12,RTM!$B$2:$B$247,"Interface") | E12: =COUNTIFS(RTM!$C$2:$C$247,$A12,RTM!$B$2:$B$247,"Exception") | F12: =COUNTIFS(RTM!$C$2:$C$247,$A12,RTM!$H$2:$H$247,"M") | G12: =COUNTIFS(RTM!$C$2:$C$247,$A12,RTM!$H$2:$H$247,"S") | H12: =COUNTIFS(RTM!$C$2:$C$247,$A12,RTM!$H$2:$H$247,"C") | I12: =COUNTIFS(RTM!$C$2:$C$247,$A12,RTM!$I$2:$I$247,"?*") | J12: =COUNTIFS(RTM!$C$2:$C$247,$A12,RTM!$N$2:$N$247,"Passed") | K12: =COUNTIFS(RTM!$C$2:$C$247,$A12,RTM!$N$2:$N$247,"Failed")+COUNTIFS(RTM!$C$2:$C$247,$A12,RTM!$N$2:$N$247,"Blocked") | L12: =COUNTIFS(RTM!$C$2:$C$247,$A12,RTM!$N$2:$N$247,"In Progress") | M12: =COUNTIFS(RTM!$C$2:$C$247,$A12,RTM!$N$2:$N$247,"Not Started") | N12: =IFERROR(J12/B12,0) | O12: =IFERROR(I12/B12,0)
A13: Cross-Docking | B13: =COUNTIFS(RTM!$C$2:$C$247,$A13) | C13: =COUNTIFS(RTM!$C$2:$C$247,$A13,RTM!$B$2:$B$247,"Requirement") | D13: =COUNTIFS(RTM!$C$2:$C$247,$A13,RTM!$B$2:$B$247,"Interface") | E13: =COUNTIFS(RTM!$C$2:$C$247,$A13,RTM!$B$2:$B$247,"Exception") | F13: =COUNTIFS(RTM!$C$2:$C$247,$A13,RTM!$H$2:$H$247,"M") | G13: =COUNTIFS(RTM!$C$2:$C$247,$A13,RTM!$H$2:$H$247,"S") | H13: =COUNTIFS(RTM!$C$2:$C$247,$A13,RTM!$H$2:$H$247,"C") | I13: =COUNTIFS(RTM!$C$2:$C$247,$A13,RTM!$I$2:$I$247,"?*") | J13: =COUNTIFS(RTM!$C$2:$C$247,$A13,RTM!$N$2:$N$247,"Passed") | K13: =COUNTIFS(RTM!$C$2:$C$247,$A13,RTM!$N$2:$N$247,"Failed")+COUNTIFS(RTM!$C$2:$C$247,$A13,RTM!$N$2:$N$247,"Blocked") | L13: =COUNTIFS(RTM!$C$2:$C$247,$A13,RTM!$N$2:$N$247,"In Progress") | M13: =COUNTIFS(RTM!$C$2:$C$247,$A13,RTM!$N$2:$N$247,"Not Started") | N13: =IFERROR(J13/B13,0) | O13: =IFERROR(I13/B13,0)
A14: Value-Added Services | B14: =COUNTIFS(RTM!$C$2:$C$247,$A14) | C14: =COUNTIFS(RTM!$C$2:$C$247,$A14,RTM!$B$2:$B$247,"Requirement") | D14: =COUNTIFS(RTM!$C$2:$C$247,$A14,RTM!$B$2:$B$247,"Interface") | E14: =COUNTIFS(RTM!$C$2:$C$247,$A14,RTM!$B$2:$B$247,"Exception") | F14: =COUNTIFS(RTM!$C$2:$C$247,$A14,RTM!$H$2:$H$247,"M") | G14: =COUNTIFS(RTM!$C$2:$C$247,$A14,RTM!$H$2:$H$247,"S") | H14: =COUNTIFS(RTM!$C$2:$C$247,$A14,RTM!$H$2:$H$247,"C") | I14: =COUNTIFS(RTM!$C$2:$C$247,$A14,RTM!$I$2:$I$247,"?*") | J14: =COUNTIFS(RTM!$C$2:$C$247,$A14,RTM!$N$2:$N$247,"Passed") | K14: =COUNTIFS(RTM!$C$2:$C$247,$A14,RTM!$N$2:$N$247,"Failed")+COUNTIFS(RTM!$C$2:$C$247,$A14,RTM!$N$2:$N$247,"Blocked") | L14: =COUNTIFS(RTM!$C$2:$C$247,$A14,RTM!$N$2:$N$247,"In Progress") | M14: =COUNTIFS(RTM!$C$2:$C$247,$A14,RTM!$N$2:$N$247,"Not Started") | N14: =IFERROR(J14/B14,0) | O14: =IFERROR(I14/B14,0)
A15: Kitting / Light Mfg | B15: =COUNTIFS(RTM!$C$2:$C$247,$A15) | C15: =COUNTIFS(RTM!$C$2:$C$247,$A15,RTM!$B$2:$B$247,"Requirement") | D15: =COUNTIFS(RTM!$C$2:$C$247,$A15,RTM!$B$2:$B$247,"Interface") | E15: =COUNTIFS(RTM!$C$2:$C$247,$A15,RTM!$B$2:$B$247,"Exception") | F15: =COUNTIFS(RTM!$C$2:$C$247,$A15,RTM!$H$2:$H$247,"M") | G15: =COUNTIFS(RTM!$C$2:$C$247,$A15,RTM!$H$2:$H$247,"S") | H15: =COUNTIFS(RTM!$C$2:$C$247,$A15,RTM!$H$2:$H$247,"C") | I15: =COUNTIFS(RTM!$C$2:$C$247,$A15,RTM!$I$2:$I$247,"?*") | J15: =COUNTIFS(RTM!$C$2:$C$247,$A15,RTM!$N$2:$N$247,"Passed") | K15: =COUNTIFS(RTM!$C$2:$C$247,$A15,RTM!$N$2:$N$247,"Failed")+COUNTIFS(RTM!$C$2:$C$247,$A15,RTM!$N$2:$N$247,"Blocked") | L15: =COUNTIFS(RTM!$C$2:$C$247,$A15,RTM!$N$2:$N$247,"In Progress") | M15: =COUNTIFS(RTM!$C$2:$C$247,$A15,RTM!$N$2:$N$247,"Not Started") | N15: =IFERROR(J15/B15,0) | O15: =IFERROR(I15/B15,0)
A16: Quality Management | B16: =COUNTIFS(RTM!$C$2:$C$247,$A16) | C16: =COUNTIFS(RTM!$C$2:$C$247,$A16,RTM!$B$2:$B$247,"Requirement") | D16: =COUNTIFS(RTM!$C$2:$C$247,$A16,RTM!$B$2:$B$247,"Interface") | E16: =COUNTIFS(RTM!$C$2:$C$247,$A16,RTM!$B$2:$B$247,"Exception") | F16: =COUNTIFS(RTM!$C$2:$C$247,$A16,RTM!$H$2:$H$247,"M") | G16: =COUNTIFS(RTM!$C$2:$C$247,$A16,RTM!$H$2:$H$247,"S") | H16: =COUNTIFS(RTM!$C$2:$C$247,$A16,RTM!$H$2:$H$247,"C") | I16: =COUNTIFS(RTM!$C$2:$C$247,$A16,RTM!$I$2:$I$247,"?*") | J16: =COUNTIFS(RTM!$C$2:$C$247,$A16,RTM!$N$2:$N$247,"Passed") | K16: =COUNTIFS(RTM!$C$2:$C$247,$A16,RTM!$N$2:$N$247,"Failed")+COUNTIFS(RTM!$C$2:$C$247,$A16,RTM!$N$2:$N$247,"Blocked") | L16: =COUNTIFS(RTM!$C$2:$C$247,$A16,RTM!$N$2:$N$247,"In Progress") | M16: =COUNTIFS(RTM!$C$2:$C$247,$A16,RTM!$N$2:$N$247,"Not Started") | N16: =IFERROR(J16/B16,0) | O16: =IFERROR(I16/B16,0)
... A22: Non-Functional | B22: =COUNTIFS(RTM!$C$2:$C$247,$A22) | C22: =COUNTIFS(RTM!$C$2:$C$247,$A22,RTM!$B$2:$B$247,"Requirement") | D22: =COUNTIFS(RTM!$C$2:$C$247,$A22,RTM!$B$2:$B$247,"Interface") | E22: =COUNTIFS(RTM!$C$2:$C$247,$A22,RTM!$B$2:$B$247,"Exception") | F22: =COUNTIFS(RTM!$C$2:$C$247,$A22,RTM!$H$2:$H$247,"M") | G22: =COUNTIFS(RTM!$C$2:$C$247,$A22,RTM!$H$2:$H$247,"S") | H22: =COUNTIFS(RTM!$C$2:$C$247,$A22,RTM!$H$2:$H$247,"C") | I22: =COUNTIFS(RTM!$C$2:$C$247,$A22,RTM!$I$2:$I$247,"?*") | J22: =COUNTIFS(RTM!$C$2:$C$247,$A22,RTM!$N$2:$N$247,"Passed") | K22: =COUNTIFS(RTM!$C$2:$C$247,$A22,RTM!$N$2:$N$247,"Failed")+COUNTIFS(RTM!$C$2:$C$247,$A22,RTM!$N$2:$N$247,"Blocked") | L22: =COUNTIFS(RTM!$C$2:$C$247,$A22,RTM!$N$2:$N$247,"In Progress") | M22: =COUNTIFS(RTM!$C$2:$C$247,$A22,RTM!$N$2:$N$247,"Not Started") | N22: =IFERROR(J22/B22,0) | O22: =IFERROR(I22/B22,0)
A23: TOTAL | B23: =SUM(B5:B22) | C23: =SUM(C5:C22) | D23: =SUM(D5:D22) | E23: =SUM(E5:E22) | F23: =SUM(F5:F22) | G23: =SUM(G5:G22) | H23: =SUM(H5:H22) | I23: =SUM(I5:I22) | ... M23: =SUM(M5:M22) | N23: =IFERROR(J23/B23,0) | O23: =IFERROR(I23/B23,0)
A25: Check: RTM row count | B25: =COUNTA(RTM!$A$2:$A$247) | C25: =IF(B25=B23,"OK - all rows mapped to an area","MISMATCH")

Sheet RTM
A1: Req ID | B1: Type | C1: Area | D1: Section | E1: Source Document | F1: Requirement / Exception | G1: Acceptance Criteria / Expected Behaviour | H1: Priority | I1: Fit-Gap Disposition | J1: Design Reference | K1: Test Case ID | L1: Test Type | M1: Test Phase | N1: Test Status | O1: Defect ID(s) | P1: Owner | Q1: Notes
A2: INB-001 | B2: Requirement | C2: Inbound | D2: 1.3 System Rules | E2: docs/scope/02-functional-inbound-storage.md | F2: Receipt against an expectation must validate the item against the expectation lines. Unexpected items are blocked unless the user holds INB_RECEIVE_UNEXPECTED. | G2: Rule/requirement enforced as stated (positive + negative case) | H2: M | K2: TC-INB-001-01 | L2: Functional (rule test harness + E2E scenario) | M2: SIT; UAT | N2: Not Started
A3: INB-002 | B3: Requirement | C3: Inbound | D3: 1.3 System Rules | E3: docs/scope/02-functional-inbound-storage.md | F3: Over-receipt tolerance is configurable per vendor, item class, and warehouse, as % and absolute units. Exceeding it requires supervisor override with a reason code. The default mirrors the ERP PO over-delivery tolerance (SAP UEBTO, Oracle QTY_RCV_TOLERANCE). | G3: Rule/requirement enforced as stated (positive + negative case) | H3: M | K3: TC-INB-002-01 | L3: Functional (rule test harness + E2E scenario) | M3: SIT; UAT | N3: Not Started
A4: INB-003 | B4: Requirement | C4: Inbound | D4: 1.3 System Rules | E4: docs/scope/02-functional-inbound-storage.md | F4: Under-receipt: a receipt may close short. The residual is reported back so the ERP can adjust the delivery or leave the PO open, as configured per flow. | G4: Rule/requirement enforced as stated (positive + negative case) | H4: M | K4: TC-INB-003-01 | L4: Functional (rule test harness + E2E scenario) | M4: SIT; UAT | N4: Not Started
A5: INB-004 | B5: Requirement | C5: Inbound | D5: 1.3 System Rules | E5: docs/scope/02-functional-inbound-storage.md | F5: Expiry validation: reject or hold when remaining shelf life < the item's *minimum remaining shelf life on receipt* (SAP MHDRZ; Oracle shelf-life days). | G5: Rule/requirement enforced as stated (positive + negative case) | H5: M | K5: TC-INB-004-01 | L5: Functional (rule test harness + E2E scenario) | M5: SIT; UAT | N5: Not Started
A6: INB-005 | B6: Requirement | C6: Inbound | D6: 1.3 System Rules | E6: docs/scope/02-functional-inbound-storage.md | F6: Lot uniqueness: the same lot number for the same item from different vendors is allowed; the system key is (item, lot, vendor-lot). | G6: Rule/requirement enforced as stated (positive + negative case) | H6: M | K6: TC-INB-005-01 | L6: Functional (rule test harness + E2E scenario) | M6: SIT; UAT | N6: Not Started
A7: INB-006 | B7: Requirement | C7: Inbound | D7: 1.3 System Rules | E7: docs/scope/02-functional-inbound-storage.md | F7: Serial capture: for serial-controlled items the count of serials must equal the received quantity in base UoM; duplicate serials within the item are rejected. | G7: Rule/requirement enforced as stated (positive + negative case) | H7: M | K7: TC-INB-006-01 | L7: Functional (rule test harness + E2E scenario) | M7: SIT; UAT | N7: Not Started
A8: INB-007 | B8: Requirement | C8: Inbound | D8: 1.3 System Rules | E8: docs/scope/02-functional-inbound-storage.md | F8: Catch weight: for catch-weight items, capture actual weight per case or per pallet within tolerance (±x%) of nominal. | G8: Rule/requirement enforced as stated (positive + negative case) | H8: S | K8: TC-INB-007-01 | L8: Functional (rule test harness + E2E scenario) | M8: SIT; UAT | N8: Not Started
A9: INB-008 | B9: Requirement | C9: Inbound | D9: 1.3 System Rules | E9: docs/scope/02-functional-inbound-storage.md | F9: Receipt date and time are stamped in site local time and UTC; the GR posting date follows ERP period rules (no posting into a closed period; next-open-period logic). | G9: Rule/requirement enforced as stated (positive + negative case) | H9: M | K9: TC-INB-008-01 | L9: Functional (rule test harness + E2E scenario) | M9: SIT; UAT | N9: Not Started
A10: INB-009 | B10: Requirement | C10: Inbound | D10: 1.3 System Rules | E10: docs/scope/02-functional-inbound-storage.md | F10: Door assignment respects temperature class, HazMat door restrictions, and door equipment (leveller, dock lock). | G10: Rule/requirement enforced as stated (positive + negative case) | H10: S | K10: TC-INB-009-01 | L10: Functional (rule test harness + E2E scenario) | M10: SIT; UAT | N10: Not Started
A11: INB-010 | B11: Requirement | C11: Inbound | D11: 1.3 System Rules | E11: docs/scope/02-functional-inbound-storage.md | F11: Appointment no-show: auto-release the slot after N minutes past the slot start; the carrier scorecard is updated. | G11: Rule/requirement enforced as stated (positive + negative case) | H11: S | K11: TC-INB-010-01 | L11: Functional (rule test harness + E2E scenario) | M11: SIT; UAT | N11: Not Started
A12: INB-011 | B12: Requirement | C12: Inbound | D12: 1.3 System Rules | E12: docs/scope/02-functional-inbound-storage.md | F12: ASN SSCC receipt must be a *single-scan* confirmation for a homogeneous pallet; mixed pallets require line-level verification, or ASN trust mode per vendor (trusted vendors can skip line-level verification). | G12: Rule/requirement enforced as stated (positive + negative case) | H12: S | K12: TC-INB-011-01 | L12: Functional (rule test harness + E2E scenario) | M12: SIT; UAT | N12: Not Started
A13: INB-012 | B13: Requirement | C13: Inbound | D13: 1.3 System Rules | E13: docs/scope/02-functional-inbound-storage.md | F13: Dock-to-stock timer starts at unload scan and ends at putaway confirmation. The timer is visible on the dashboard; an SLA breach raises an alert. | G13: Rule/requirement enforced as stated (positive + negative case) | H13: S | K13: TC-INB-012-01 | L13: Functional (rule test harness + E2E scenario) | M13: SIT; UAT | N13: Not Started
A14: INB-EX-01 | B14: Exception | C14: Inbound | D14: 1.5 Exception Handling | E14: docs/scope/02-functional-inbound-storage.md | F14: Seal mismatch or broken | G14: Detection: Seal scan ≠ ASN seal | Resolution: Hold trailer; photo capture; supervisor decides to accept (record) or reject (trailer refused) | ERP impact: None until receipt; claim flagged | H14: M | K14: TC-INB-EX-01-01 | L14: Negative / exception scenario | M14: SIT; UAT | N14: Not Started | Q14: Priority defaulted to M (exception flow; see Legend)
A15: INB-EX-02 | B15: Exception | C15: Inbound | D15: 1.5 Exception Handling | E15: docs/scope/02-functional-inbound-storage.md | F15: Over-receipt beyond tolerance | G15: Detection: Qty validation | Resolution: Supervisor override (reason) or receive excess into OVERAGE status location pending buyer decision | ERP impact: ERP PO increase or return-to-vendor | H15: M | K15: TC-INB-EX-02-01 | L15: Negative / exception scenario | M15: SIT; UAT | N15: Not Started | Q15: Priority defaulted to M (exception flow; see Legend)
A16: INB-EX-03 | B16: Exception | C16: Inbound | D16: 1.5 Exception Handling | E16: docs/scope/02-functional-inbound-storage.md | F16: Short receipt | G16: Detection: Receipt closed < expected | Resolution: Reason code (vendor short, damaged, in transit); auto-generate vendor discrepancy report (EDI 861 optional) | ERP impact: Delivery quantity adjusted; PO remains open or closed per config | H16: M | K16: TC-INB-EX-03-01 | L16: Negative / exception scenario | M16: SIT; UAT | N16: Not Started | Q16: Priority defaulted to M (exception flow; see Legend)
A17: INB-EX-04 | B17: Exception | C17: Inbound | D17: 1.5 Exception Handling | E17: docs/scope/02-functional-inbound-storage.md | F17: Damaged goods | G17: Detection: User flags damage | Resolution: Received into DAMAGED status; photo evidence; creates claim record; route to damage cage | ERP impact: GR to blocked stock (SAP stock type S; Oracle hold status) | H17: M | K17: TC-INB-EX-04-01 | L17: Negative / exception scenario | M17: SIT; UAT | N17: Not Started | Q17: Priority defaulted to M (exception flow; see Legend)
A18: INB-EX-05 | B18: Exception | C18: Inbound | D18: 1.5 Exception Handling | E18: docs/scope/02-functional-inbound-storage.md | F18: Unknown item or GTIN not in master | G18: Detection: Scan resolution fails | Resolution: Item placed in UNKNOWN holding location; master data request to ERP; auto-retry mapping when the master arrives | ERP impact: None until resolved | H18: M | K18: TC-INB-EX-05-01 | L18: Negative / exception scenario | M18: SIT; UAT | N18: Not Started | Q18: Priority defaulted to M (exception flow; see Legend)
A19: INB-EX-06 | B19: Exception | C19: Inbound | D19: 1.5 Exception Handling | E19: docs/scope/02-functional-inbound-storage.md | F19: Expiry below minimum | G19: Detection: INB-004 | Resolution: Reject (refuse at dock) or receive to QI for QA decision | ERP impact: Blocked or QI stock | H19: M | K19: TC-INB-EX-06-01 | L19: Negative / exception scenario | M19: SIT; UAT | N19: Not Started | Q19: Priority defaulted to M (exception flow; see Legend)
A20: INB-EX-07 | B20: Exception | C20: Inbound | D20: 1.5 Exception Handling | E20: docs/scope/02-functional-inbound-storage.md | F20: ASN SSCC not found / duplicate SSCC | G20: Detection: SSCC lookup | Resolution: Convert to line-level receipt; relabel with WMS LPN | ERP impact: None | H20: M | K20: TC-INB-EX-07-01 | L20: Negative / exception scenario | M20: SIT; UAT | N20: Not Started | Q20: Priority defaulted to M (exception flow; see Legend)
A21: INB-EX-08 | B21: Exception | C21: Inbound | D21: 1.5 Exception Handling | E21: docs/scope/02-functional-inbound-storage.md | F21: Lot/serial mismatch with ASN | G21: Detection: Attribute validation | Resolution: Accept actual lot (ERP batch created by message) or hold, per vendor rule | ERP impact: Batch creation (SAP BATMAS/BAPI_BATCH_CREATE) | H21: M | K21: TC-INB-EX-08-01 | L21: Negative / exception scenario | M21: SIT; UAT | N21: Not Started | Q21: Priority defaulted to M (exception flow; see Legend)
A22: INB-EX-09 | B22: Exception | C22: Inbound | D22: 1.5 Exception Handling | E22: docs/scope/02-functional-inbound-storage.md | F22: Receipt with no expectation (blind) | G22: Detection: No ASN | Resolution: Permission-controlled; creates unplanned receipt; ERP document requested/created by inbound message | ERP impact: ERP creates inbound delivery / unordered receipt | H22: M | K22: TC-INB-EX-09-01 | L22: Negative / exception scenario | M22: SIT; UAT | N22: Not Started | Q22: Priority defaulted to M (exception flow; see Legend)
A23: INB-EX-10 | B23: Exception | C23: Inbound | D23: 1.5 Exception Handling | E23: docs/scope/02-functional-inbound-storage.md | F23: Temperature excursion on arrival | G23: Detection: Reefer reading outside range | Resolution: Hold entire load; QA notification; §14 cold-chain flow | ERP impact: QI stock | H23: M | K23: TC-INB-EX-10-01 | L23: Negative / exception scenario | M23: SIT; UAT | N23: Not Started | Q23: Priority defaulted to M (exception flow; see Legend)
A24: INB-EX-11 | B24: Exception | C24: Inbound | D24: 1.5 Exception Handling | E24: docs/scope/02-functional-inbound-storage.md | F24: ERP change after receipt started | G24: Detection: Delivery update message for an IN_PROGRESS expectation | Resolution: Change queued; supervisor must accept/reject; qty reduction below the received qty is rejected back to ERP | ERP impact: Error reply to ERP | H24: M | K24: TC-INB-EX-11-01 | L24: Negative / exception scenario | M24: SIT; UAT | N24: Not Started | Q24: Priority defaulted to M (exception flow; see Legend)
A25: PUT-001 | B25: Requirement | C25: Putaway & Storage | D25: 2.4 System Rules | E25: docs/scope/02-functional-inbound-storage.md | F25: Compatibility filters (temperature, HazMat segregation, bonded, owner segregation) are hard constraints; overrides are impossible for any role. | G25: Rule/requirement enforced as stated (positive + negative case) | H25: M | K25: TC-PUT-001-01 | L25: Functional (rule test harness + E2E scenario) | M25: SIT; UAT | N25: Not Started
A26: PUT-002 | B26: Requirement | C26: Putaway & Storage | D26: 2.4 System Rules | E26: docs/scope/02-functional-inbound-storage.md | F26: Scan of location check digit required to confirm. Alternate location override requires permission PUT_OVERRIDE and is validated against PUT-001 plus capacity. | G26: Rule/requirement enforced as stated (positive + negative case) | H26: M | K26: TC-PUT-002-01 | L26: Functional (rule test harness + E2E scenario) | M26: SIT; UAT | N26: Not Started
A27: PUT-003 | B27: Requirement | C27: Putaway & Storage | D27: 2.4 System Rules | E27: docs/scope/02-functional-inbound-storage.md | F27: Multi-LPN putaway: an operator may carry up to N LPNs (per equipment type); the system sequences drops by optimal route. | G27: Rule/requirement enforced as stated (positive + negative case) | H27: S | K27: TC-PUT-003-01 | L27: Functional (rule test harness + E2E scenario) | M27: SIT; UAT | N27: Not Started
A28: PUT-004 | B28: Requirement | C28: Putaway & Storage | D28: 2.4 System Rules | E28: docs/scope/02-functional-inbound-storage.md | F28: Partial putaway: the operator may split an LPN when the target is full; the remainder gets a new task. | G28: Rule/requirement enforced as stated (positive + negative case) | H28: M | K28: TC-PUT-004-01 | L28: Functional (rule test harness + E2E scenario) | M28: SIT; UAT | N28: Not Started
A29: PUT-005 | B29: Requirement | C29: Putaway & Storage | D29: 2.4 System Rules | E29: docs/scope/02-functional-inbound-storage.md | F29: Putaway to QI locations only for QI-status stock; available stock cannot be put into QC zones. | G29: Rule/requirement enforced as stated (positive + negative case) | H29: M | K29: TC-PUT-005-01 | L29: Functional (rule test harness + E2E scenario) | M29: SIT; UAT | N29: Not Started
A30: PUT-006 | B30: Requirement | C30: Putaway & Storage | D30: 2.4 System Rules | E30: docs/scope/02-functional-inbound-storage.md | F30: Stock at dock is visible but *not allocable* until it is put away, unless cross-dock/flow-through is enabled. | G30: Rule/requirement enforced as stated (positive + negative case) | H30: M | K30: TC-PUT-006-01 | L30: Functional (rule test harness + E2E scenario) | M30: SIT; UAT | N30: Not Started
A31: PUT-007 | B31: Requirement | C31: Putaway & Storage | D31: 2.4 System Rules | E31: docs/scope/02-functional-inbound-storage.md | F31: Putaway tasks are prioritised by: cross-dock urgency > dock congestion (door needed) > dock age > FIFO. | G31: Rule/requirement enforced as stated (positive + negative case) | H31: S | K31: TC-PUT-007-01 | L31: Functional (rule test harness + E2E scenario) | M31: SIT; UAT | N31: Not Started
A32: PUT-008 | B32: Requirement | C32: Putaway & Storage | D32: 2.4 System Rules | E32: docs/scope/02-functional-inbound-storage.md | F32: Storage zone moves (internal relocation) use the same engine with source ≠ dock. | G32: Rule/requirement enforced as stated (positive + negative case) | H32: M | K32: TC-PUT-008-01 | L32: Functional (rule test harness + E2E scenario) | M32: SIT; UAT | N32: Not Started
A33: PUT-EX-01 | B33: Exception | C33: Putaway & Storage | D33: 2.7 Exception Handling | E33: docs/scope/02-functional-inbound-storage.md | F33: No location available | G33: Resolution: Route to overflow zone; alert inventory control; capacity report; slotting review flag | H33: M | K33: TC-PUT-EX-01-01 | L33: Negative / exception scenario | M33: SIT; UAT | N33: Not Started | Q33: Priority defaulted to M (exception flow; see Legend)
A34: PUT-EX-02 | B34: Exception | C34: Putaway & Storage | D34: 2.7 Exception Handling | E34: docs/scope/02-functional-inbound-storage.md | F34: Target location occupied or damaged on arrival | G34: Resolution: Operator reports "location blocked", with location auto-blocked and a count task created; engine re-directs | H34: M | K34: TC-PUT-EX-02-01 | L34: Negative / exception scenario | M34: SIT; UAT | N34: Not Started | Q34: Priority defaulted to M (exception flow; see Legend)
A35: PUT-EX-03 | B35: Exception | C35: Putaway & Storage | D35: 2.7 Exception Handling | E35: docs/scope/02-functional-inbound-storage.md | F35: LPN over-height / overweight for target | G35: Resolution: Operator reports; LPN dims updated; re-evaluate | H35: M | K35: TC-PUT-EX-03-01 | L35: Negative / exception scenario | M35: SIT; UAT | N35: Not Started | Q35: Priority defaulted to M (exception flow; see Legend)
A36: PUT-EX-04 | B36: Exception | C36: Putaway & Storage | D36: 2.7 Exception Handling | E36: docs/scope/02-functional-inbound-storage.md | F36: LPN not found at dock | G36: Resolution: Search task; if not found in X min, LPN flagged missing; inventory held; supervisor investigation | H36: M | K36: TC-PUT-EX-04-01 | L36: Negative / exception scenario | M36: SIT; UAT | N36: Not Started | Q36: Priority defaulted to M (exception flow; see Legend)
A37: PUT-EX-05 | B37: Exception | C37: Putaway & Storage | D37: 2.7 Exception Handling | E37: docs/scope/02-functional-inbound-storage.md | F37: Wrong LPN scanned | G37: Resolution: Hard stop; directs to the correct LPN or swaps the task to the scanned LPN if valid | H37: M | K37: TC-PUT-EX-05-01 | L37: Negative / exception scenario | M37: SIT; UAT | N37: Not Started | Q37: Priority defaulted to M (exception flow; see Legend)
A38: PUT-EX-06 | B38: Exception | C38: Putaway & Storage | D38: 2.7 Exception Handling | E38: docs/scope/02-functional-inbound-storage.md | F38: Equipment breakdown mid-task | G38: Resolution: Task suspended with LPN at a drop location (P&D point); re-queued for other equipment | H38: M | K38: TC-PUT-EX-06-01 | L38: Negative / exception scenario | M38: SIT; UAT | N38: Not Started | Q38: Priority defaulted to M (exception flow; see Legend)
A39: OUT-001 | B39: Requirement | C39: Outbound Order Mgmt | D39: 3.5 System Rules | E39: docs/scope/03-functional-outbound.md | F39: Orders with ERP delivery block or credit hold are received but not allocable. | G39: Rule/requirement enforced as stated (positive + negative case) | H39: M | K39: TC-OUT-001-01 | L39: Functional (rule test harness + E2E scenario) | M39: SIT; UAT | N39: Not Started
A40: OUT-002 | B40: Requirement | C40: Outbound Order Mgmt | D40: 3.5 System Rules | E40: docs/scope/03-functional-outbound.md | F40: ERP delivery changes (qty increase/decrease, line add/delete) accepted while status < RELEASED; after release, change requests generate supervisor workflow. | G40: Rule/requirement enforced as stated (positive + negative case) | H40: M | K40: TC-OUT-002-01 | L40: Functional (rule test harness + E2E scenario) | M40: SIT; UAT | N40: Not Started
...
